<sdf version='1.6'>
  <world name='default'>
    <light name='sun' type='directional'>
      <cast_shadows>1</cast_shadows>
      <pose frame=''>0 0 10 0 -0 0</pose>
      <diffuse>0.8 0.8 0.8 1</diffuse>
      <specular>0.2 0.2 0.2 1</specular>
      <attenuation>
        <range>1000</range>
        <constant>0.9</constant>
        <linear>0.01</linear>
        <quadratic>0.001</quadratic>
      </attenuation>
      <direction>-0.5 0.1 -0.9</direction>
    </light>
    <model name='ground_plane'>
      <static>1</static>
      <link name='link'>
        <collision name='collision'>
          <geometry>
            <plane>
              <normal>0 0 1</normal>
              <size>100 100</size>
            </plane>
          </geometry>
          <surface>
            <contact>
              <collide_bitmask>65535</collide_bitmask>
              <ode/>
            </contact>
            <friction>
              <ode>
                <mu>100</mu>
                <mu2>50</mu2>
              </ode>
              <torsional>
                <ode/>
              </torsional>
            </friction>
            <bounce/>
          </surface>
          <max_contacts>10</max_contacts>
        </collision>
        <visual name='visual'>
          <cast_shadows>0</cast_shadows>
          <geometry>
            <plane>
              <normal>0 0 1</normal>
              <size>100 100</size>
            </plane>
          </geometry>
          <material>
            <script>
              <uri>file://media/materials/scripts/gazebo.material</uri>
              <name>Gazebo/White</name>
            </script>
          </material>
        </visual>
        <self_collide>0</self_collide>
        <enable_wind>0</enable_wind>
        <kinematic>0</kinematic>
      </link>
    </model>
    <gravity>0 0 -9.8</gravity>
    <magnetic_field>6e-06 2.3e-05 -4.2e-05</magnetic_field>
    <atmosphere type='adiabatic'/>
    <physics name='default_physics' default='0' type='ode'>
      <max_step_size>0.001</max_step_size>
      <real_time_factor>1</real_time_factor>
      <real_time_update_rate>1000</real_time_update_rate>
    </physics>
    <scene>
      <ambient>0.4 0.4 0.4 1</ambient>
      <background>0.9 0.9 0.9 1</background>
      <shadows>1</shadows>
    </scene>
    <wind/>
    <spherical_coordinates>
      <surface_model>EARTH_WGS84</surface_model>
      <latitude_deg>0</latitude_deg>
      <longitude_deg>0</longitude_deg>
      <elevation>0</elevation>
      <heading_deg>0</heading_deg>
    </spherical_coordinates>
    <model name='kinect'>
      <pose frame=''>0.375701 0.005515 0.036 0 -0 0</pose>
      <static>1</static>
      <link name='link'>
        <inertial>
          <mass>0.1</mass>
        </inertial>
        <collision name='collision'>
          <geometry>
            <box>
              <size>0.073 0.276 0.072</size>
            </box>
          </geometry>
          <max_contacts>10</max_contacts>
          <surface>
            <contact>
              <ode/>
            </contact>
            <bounce/>
            <friction>
              <torsional>
                <ode/>
              </torsional>
              <ode/>
            </friction>
          </surface>
        </collision>
        <visual name='visual'>
          <geometry>
            <mesh>
              <uri>model://kinect/meshes/kinect.dae</uri>
            </mesh>
          </geometry>
        </visual>
        <sensor name='camera' type='depth'>
          <update_rate>20</update_rate>
          <camera name='__default__'>
            <horizontal_fov>0.524</horizontal_fov>
            <image>
              <width>400</width>
              <height>400</height>
              <format>R8G8B8</format>
            </image>
            <clip>
              <near>0.5</near>
              <far>2.5</far>
            </clip>
          </camera>
          <plugin name='camera_plugin' filename='libgazebo_ros_openni_kinect.so'>
            <baseline>0.2</baseline>
            <alwaysOn>1</alwaysOn>
            <updateRate>0.0</updateRate>
            <cameraName>camera_ir</cameraName>
            <imageTopicName>/camera/color/image_raw</imageTopicName>
            <cameraInfoTopicName>/camera/color/camera_info</cameraInfoTopicName>
            <depthImageTopicName>/camera/depth/image_raw</depthImageTopicName>
            <depthImageCameraInfoTopicName>/camera/depth/camera_info</depthImageCameraInfoTopicName>
            <pointCloudTopicName>/camera/depth/points</pointCloudTopicName>
            <frameName>camera_link</frameName>
            <pointCloudCutoff>0.5</pointCloudCutoff>
            <pointCloudCutoffMax>3.0</pointCloudCutoffMax>
            <distortionK1>0</distortionK1>
            <distortionK2>0</distortionK2>
            <distortionK3>0</distortionK3>
            <distortionT1>0</distortionT1>
            <distortionT2>0</distortionT2>
            <CxPrime>0</CxPrime>
            <Cx>0</Cx>
            <Cy>0</Cy>
            <focalLength>0</focalLength>
            <hackBaseline>0</hackBaseline>
          </plugin>
        </sensor>
        <self_collide>0</self_collide>
        <enable_wind>0</enable_wind>
        <kinematic>0</kinematic>
      </link>
    </model>
    <state world_name='default'>
      <sim_time>7399 154000000</sim_time>
      <real_time>28 769709665</real_time>
      <wall_time>1615908709 37860957</wall_time>
      <iterations>28224</iterations>
      <model name='cafe_table'>
        <pose frame=''>0.85972 -0.008612 -0.760473 0 -0 0</pose>
        <scale>1 1 1</scale>
        <link name='link'>
          <pose frame=''>0.85972 -0.008612 -0.760473 0 -0 0</pose>
          <velocity>0 0 0 0 -0 0</velocity>
          <acceleration>0 0 0 0 -0 0</acceleration>
          <wrench>0 0 0 0 -0 0</wrench>
        </link>
      </model>
      <model name='ground_plane'>
        <pose frame=''>0 0 0 0 -0 0</pose>
        <scale>1 1 1</scale>
        <link name='link'>
          <pose frame=''>0 0 0 0 -0 0</pose>
          <velocity>0 0 0 0 -0 0</velocity>
          <acceleration>0 0 0 0 -0 0</acceleration>
          <wrench>0 0 0 0 -0 0</wrench>
        </link>
      </model>
      <model name='kinect'>
        <pose frame=''>0.115108 -0.340812 0.632272 -0.000972 0.599242 0.442926</pose>
        <scale>1 1 1</scale>
        <link name='link'>
          <pose frame=''>0.115108 -0.340812 0.632272 -0.000972 0.599242 0.442926</pose>
          <velocity>0 0 0 0 -0 0</velocity>
          <acceleration>0 0 0 0 -0 0</acceleration>
          <wrench>0 0 0 0 -0 0</wrench>
        </link>
      </model>
      <model name='panda'>
        <pose frame=''>2e-06 -2e-06 1.8e-05 -0.000141 -7.3e-05 1.1e-05</pose>
        <scale>1 1 1</scale>
        <link name='panda_leftfinger'>
          <pose frame=''>-0.088993 -0.038083 1.198 0.000174 0.001999 -3.12663</pose>
          <velocity>-0.001881 5.2e-05 0.000332 -0.00282 -0.024784 0.003129</velocity>
          <acceleration>-4.81556 -0.251948 0.786092 -1.73011 -0.614402 2.44289</acceleration>
          <wrench>-0.481556 -0.025195 0.078609 0 -0 0</wrench>
        </link>
        <link name='panda_link0'>
          <pose frame=''>2e-06 -2e-06 1.8e-05 -0.000141 -7.3e-05 1.1e-05</pose>
          <velocity>2.1e-05 -8.6e-05 -0.00205 -0.012717 0.006694 0.000498</velocity>
          <acceleration>0.781851 1.3327 -3.73994 0.03543 1.0897 0.689923</acceleration>
          <wrench>2.283 3.89147 -10.9206 0 -0 0</wrench>
        </link>
        <link name='panda_link1'>
          <pose frame=''>-2.8e-05 3.9e-05 0.333018 -0.000102 -0.0001 0.000143</pose>
          <velocity>0.002689 0.002754 -0.00219 -0.000585 0.008855 0.022384</velocity>
          <acceleration>5.67174 5.62169 -4.27251 -2.75644 -0.817619 1.60525</acceleration>
          <wrench>15.5406 15.4034 -11.7067 0 -0 0</wrench>
        </link>
        <link name='panda_link2'>
          <pose frame=''>-2.8e-05 3.7e-05 0.333019 -1.57089 -8.9e-05 0.000144</pose>
          <velocity>0.002636 0.002354 -0.002039 0.002706 -0.032288 0.02295</velocity>
          <acceleration>-0.629763 4.76477 -3.94899 0.700489 0.882301 1.49386</acceleration>
          <wrench>-1.72555 13.0555 -10.8202 0 -0 0</wrench>
        </link>
        <link name='panda_link3'>
          <pose frame=''>-5.7e-05 6e-05 0.649017 -7.3e-05 -7.3e-05 -1.2e-05</pose>
          <velocity>-0.007553 0.000451 -0.002257 0.006188 -0.029802 -0.021503</velocity>
          <acceleration>-11.9022 0.332229 -1.39586 1.23439 -0.728386 -2.67353</acceleration>
          <wrench>-28.3273 0.790705 -3.32215 0 -0 0</wrench>
        </link>
        <link name='panda_link4'>
          <pose frame=''>0.082445 6e-05 0.649025 1.57071 -0.003068 -2.3e-05</pose>
          <velocity>-0.007316 -0.001332 0.000429 0.004822 0.024765 -0.022567</velocity>
          <acceleration>-14.0514 -0.161708 2.4057 2.27742 1.35956 -2.36203</acceleration>
          <wrench>-33.4424 -0.384864 5.72557 0 -0 0</wrench>
        </link>
        <link name='panda_link5'>
          <pose frame=''>-0.001233 9.9e-05 1.03277 -0.000127 -0.00306 0.000126</pose>
          <velocity>0.00203 -0.00083 0.0024 -0.000553 0.025541 0.002351</velocity>
          <acceleration>-2.07458 -0.305965 4.59667 -0.554345 1.45725 -2.96349</acceleration>
          <wrench>-5.68436 -0.838345 12.5949 0 -0 0</wrench>
        </link>
        <link name='panda_link6'>
          <pose frame=''>-0.001232 9.9e-05 1.03277 -1.57067 0.002019 -3.14146</pose>
          <velocity>0.002133 -0.000766 0.002448 -0.00057 -0.025093 0.003101</velocity>
          <acceleration>5.37548 -0.887702 2.32841 -2.3865 1.47917 -3.04466</acceleration>
          <wrench>8.33199 -1.37594 3.60904 0 -0 0</wrench>
        </link>
        <link name='panda_link7'>
          <pose frame=''>-0.089232 8.8e-05 1.03259 0.00155 0.001307 -2.34127</pose>
          <velocity>0.00218 -0.000928 0.000241 -0.002176 -0.025089 0.002379</velocity>
          <acceleration>-0.626535 -0.672282 0.428421 2.05056 0.410247 -0.756193</acceleration>
          <wrench>-0.7957 -0.853799 0.544095 0 -0 0</wrench>
        </link>
        <link name='panda_rightfinger'>
          <pose frame=''>-0.090159 0.040105 1.19799 0.000181 0.001998 -3.1267</pose>
          <velocity>-0.002044 6.1e-05 0.00011 -0.002799 -0.024637 0.001525</velocity>
          <acceleration>-4.88118 -0.252699 0.152872 -1.72407 -0.303077 -1.09257</acceleration>
          <wrench>-0.488118 -0.02527 0.015287 0 -0 0</wrench>
        </link>
      </model>
      <light name='sun'>
        <pose frame=''>0 0 10 0 -0 0</pose>
      </light>
    </state>
    <gui fullscreen='0'>
      <camera name='user_camera'>
        <pose frame=''>0.951967 4.55988 4.08875 -0 0.883641 -1.31018</pose>
        <view_controller>orbit</view_controller>
        <projection_type>perspective</projection_type>
      </camera>
    </gui>
    <model name='panda'>
      <link name='panda_link0'>
        <pose frame=''>0 0 0 0 -0 0</pose>
        <inertial>
          <pose frame=''>-0.025566 -2.9e-05 0.057332 0 -0 0</pose>
          <mass>2.92</mass>
          <inertia>
            <ixx>0.00782229</ixx>
            <ixy>-1.56192e-05</ixy>
            <ixz>-0.00126006</ixz>
            <iyy>0.0109028</iyy>
            <iyz>1.08234e-05</iyz>
            <izz>0.0102356</izz>
          </inertia>
        </inertial>
        <collision name='panda_link0_collision'>
          <pose frame=''>0 0 0 0 -0 0</pose>
          <geometry>
            <mesh>
              <scale>1 1 1</scale>
              <uri>/home/ollie/mmp_ws/src/franka_gazebo/meshes/collision/link0.stl</uri>
            </mesh>
          </geometry>
          <max_contacts>10</max_contacts>
          <surface>
            <contact>
              <ode/>
            </contact>
            <bounce/>
            <friction>
              <torsional>
                <ode/>
              </torsional>
              <ode/>
            </friction>
          </surface>
        </collision>
        <visual name='panda_link0_visual'>
          <pose frame=''>0 0 0 0 -0 0</pose>
          <geometry>
            <mesh>
              <scale>1 1 1</scale>
              <uri>/home/ollie/mmp_ws/src/franka_gazebo/meshes/visual/link0.dae</uri>
            </mesh>
          </geometry>
        </visual>
        <gravity>1</gravity>
        <velocity_decay/>
        <self_collide>0</self_collide>
        <enable_wind>0</enable_wind>
        <kinematic>0</kinematic>
      </link>
      <joint name='panda_joint_world' type='fixed'>
        <child>panda_link0</child>
        <parent>world</parent>
      </joint>
      <link name='panda_link1'>
        <pose frame=''>0 0 0.333 0 -0 0</pose>
        <inertial>
          <pose frame=''>0 -0.032496 -0.067582 0 -0 0</pose>
          <mass>2.74</mass>
          <inertia>
            <ixx>0.0180417</ixx>
            <ixy>0</ixy>
            <ixz>0</ixz>
            <iyy>0.0159136</iyy>
            <iyz>0.00467584</iyz>
            <izz>0.00620691</izz>
          </inertia>
        </inertial>
        <collision name='panda_link1_collision'>
          <pose frame=''>0 0 0 0 -0 0</pose>
          <geometry>
            <mesh>
              <scale>1 1 1</scale>
              <uri>/home/ollie/mmp_ws/src/franka_gazebo/meshes/collision/link1.stl</uri>
            </mesh>
          </geometry>
          <max_contacts>10</max_contacts>
          <surface>
            <contact>
              <ode/>
            </contact>
            <bounce/>
            <friction>
              <torsional>
                <ode/>
              </torsional>
              <ode/>
            </friction>
          </surface>
        </collision>
        <visual name='panda_link1_visual'>
          <pose frame=''>0 0 0 0 -0 0</pose>
          <geometry>
            <mesh>
              <scale>1 1 1</scale>
              <uri>/home/ollie/mmp_ws/src/franka_gazebo/meshes/visual/link1.dae</uri>
            </mesh>
          </geometry>
        </visual>
        <gravity>1</gravity>
        <velocity_decay/>
        <self_collide>0</self_collide>
        <enable_wind>0</enable_wind>
        <kinematic>0</kinematic>
      </link>
      <joint name='panda_joint1' type='revolute'>
        <child>panda_link1</child>
        <parent>panda_link0</parent>
        <axis>
          <xyz>0 0 1</xyz>
          <limit>
            <lower>-2.8973</lower>
            <upper>2.8973</upper>
            <effort>87</effort>
            <velocity>2.175</velocity>
          </limit>
          <dynamics>
            <spring_reference>0</spring_reference>
            <spring_stiffness>0</spring_stiffness>
          </dynamics>
          <use_parent_model_frame>1</use_parent_model_frame>
        </axis>
      </joint>
      <link name='panda_link2'>
        <pose frame=''>0 0 0.333 -1.5708 0 0</pose>
        <inertial>
          <pose frame=''>0 -0.06861 0.032229 0 -0 0</pose>
          <mass>2.74</mass>
          <inertia>
            <ixx>0.0182856</ixx>
            <ixy>0</ixy>
            <ixz>0</ixz>
            <iyy>0.00621358</iyy>
            <iyz>-0.00472844</iyz>
            <izz>0.0161514</izz>
          </inertia>
        </inertial>
        <collision name='panda_link2_collision'>
          <pose frame=''>0 0 0 0 -0 0</pose>
          <geometry>
            <mesh>
              <scale>1 1 1</scale>
              <uri>/home/ollie/mmp_ws/src/franka_gazebo/meshes/collision/link2.stl</uri>
            </mesh>
          </geometry>
          <max_contacts>10</max_contacts>
          <surface>
            <contact>
              <ode/>
            </contact>
            <bounce/>
            <friction>
              <torsional>
                <ode/>
              </torsional>
              <ode/>
            </friction>
          </surface>
        </collision>
        <visual name='panda_link2_visual'>
          <pose frame=''>0 0 0 0 -0 0</pose>
          <geometry>
            <mesh>
              <scale>1 1 1</scale>
              <uri>/home/ollie/mmp_ws/src/franka_gazebo/meshes/visual/link2.dae</uri>
            </mesh>
          </geometry>
        </visual>
        <gravity>1</gravity>
        <velocity_decay/>
        <self_collide>0</self_collide>
        <enable_wind>0</enable_wind>
        <kinematic>0</kinematic>
      </link>
      <joint name='panda_joint2' type='revolute'>
        <child>panda_link2</child>
        <parent>panda_link1</parent>
        <axis>
          <xyz>0 1 0</xyz>
          <limit>
            <lower>-1.7628</lower>
            <upper>1.7628</upper>
            <effort>87</effort>
            <velocity>2.175</velocity>
          </limit>
          <dynamics>
            <spring_reference>0</spring_reference>
            <spring_stiffness>0</spring_stiffness>
          </dynamics>
          <use_parent_model_frame>1</use_parent_model_frame>
        </axis>
      </joint>
      <link name='panda_link3'>
        <pose frame=''>0 -0 0.649 0 -0 0</pose>
        <inertial>
          <pose frame=''>0.046989 0.031637 -0.031704 0 -0 0</pose>
          <mass>2.38</mass>
          <inertia>
            <ixx>0.00771377</ixx>
            <ixy>-0.00248491</ixy>
            <ixz>-0.00332148</ixz>
            <iyy>0.00989108</iyy>
            <iyz>-0.00217796</iyz>
            <izz>0.00811724</izz>
          </inertia>
        </inertial>
        <collision name='panda_link3_collision'>
          <pose frame=''>0 0 0 0 -0 0</pose>
          <geometry>
            <mesh>
              <scale>1 1 1</scale>
              <uri>/home/ollie/mmp_ws/src/franka_gazebo/meshes/collision/link3.stl</uri>
            </mesh>
          </geometry>
          <max_contacts>10</max_contacts>
          <surface>
            <contact>
              <ode/>
            </contact>
            <bounce/>
            <friction>
              <torsional>
                <ode/>
              </torsional>
              <ode/>
            </friction>
          </surface>
        </collision>
        <visual name='panda_link3_visual'>
          <pose frame=''>0 0 0 0 -0 0</pose>
          <geometry>
            <mesh>
              <scale>1 1 1</scale>
              <uri>/home/ollie/mmp_ws/src/franka_gazebo/meshes/visual/link3.dae</uri>
            </mesh>
          </geometry>
        </visual>
        <gravity>1</gravity>
        <velocity_decay/>
        <self_collide>0</self_collide>
        <enable_wind>0</enable_wind>
        <kinematic>0</kinematic>
      </link>
      <joint name='panda_joint3' type='revolute'>
        <child>panda_link3</child>
        <parent>panda_link2</parent>
        <axis>
          <xyz>0 0 1</xyz>
          <limit>
            <lower>-2.8973</lower>
            <upper>2.8973</upper>
            <effort>87</effort>
            <velocity>2.175</velocity>
          </limit>
          <dynamics>
            <spring_reference>0</spring_reference>
            <spring_stiffness>0</spring_stiffness>
          </dynamics>
          <use_parent_model_frame>1</use_parent_model_frame>
        </axis>
      </joint>
      <link name='panda_link4'>
        <pose frame=''>0.0825 -0 0.649 1.5708 -0 0</pose>
        <inertial>
          <pose frame=''>-0.036045 0.033685 0.031882 0 -0 0</pose>
          <mass>2.38</mass>
          <inertia>
            <ixx>0.00799664</ixx>
            <ixy>0.00347096</ixy>
            <ixz>-0.00241223</ixz>
            <iyy>0.00825391</iyy>
            <iyz>0.00235774</iyz>
            <izz>0.0102515</izz>
          </inertia>
        </inertial>
        <collision name='panda_link4_collision'>
          <pose frame=''>0 0 0 0 -0 0</pose>
          <geometry>
            <mesh>
              <scale>1 1 1</scale>
              <uri>/home/ollie/mmp_ws/src/franka_gazebo/meshes/collision/link4.stl</uri>
            </mesh>
          </geometry>
          <max_contacts>10</max_contacts>
          <surface>
            <contact>
              <ode/>
            </contact>
            <bounce/>
            <friction>
              <torsional>
                <ode/>
              </torsional>
              <ode/>
            </friction>
          </surface>
        </collision>
        <visual name='panda_link4_visual'>
          <pose frame=''>0 0 0 0 -0 0</pose>
          <geometry>
            <mesh>
              <scale>1 1 1</scale>
              <uri>/home/ollie/mmp_ws/src/franka_gazebo/meshes/visual/link4.dae</uri>
            </mesh>
          </geometry>
        </visual>
        <gravity>1</gravity>
        <velocity_decay/>
        <self_collide>0</self_collide>
        <enable_wind>0</enable_wind>
        <kinematic>0</kinematic>
      </link>
      <joint name='panda_joint4' type='revolute'>
        <child>panda_link4</child>
        <parent>panda_link3</parent>
        <axis>
          <xyz>0 -1 0</xyz>
          <limit>
            <lower>-3.0718</lower>
            <upper>0.0698</upper>
            <effort>87</effort>
            <velocity>2.175</velocity>
          </limit>
          <dynamics>
            <spring_reference>0</spring_reference>
            <spring_stiffness>0</spring_stiffness>
          </dynamics>
          <use_parent_model_frame>1</use_parent_model_frame>
        </axis>
      </joint>
      <link name='panda_link5'>
        <pose frame=''>-0 0 1.033 0 -0 0</pose>
        <inertial>
          <pose frame=''>0 0.061043 -0.104176 0 -0 0</pose>
          <mass>2.74</mass>
          <inertia>
            <ixx>0.0303714</ixx>
            <ixy>6.50284e-07</ixy>
            <ixz>-1.05129e-05</ixz>
            <iyy>0.0288753</iyy>
            <iyz>-0.00775653</iyz>
            <izz>0.00444134</izz>
          </inertia>
        </inertial>
        <collision name='panda_link5_collision'>
          <pose frame=''>0 0 0 0 -0 0</pose>
          <geometry>
            <mesh>
              <scale>1 1 1</scale>
              <uri>/home/ollie/mmp_ws/src/franka_gazebo/meshes/collision/link5.stl</uri>
            </mesh>
          </geometry>
          <max_contacts>10</max_contacts>
          <surface>
            <contact>
              <ode/>
            </contact>
            <bounce/>
            <friction>
              <torsional>
                <ode/>
              </torsional>
              <ode/>
            </friction>
          </surface>
        </collision>
        <visual name='panda_link5_visual'>
          <pose frame=''>0 0 0 0 -0 0</pose>
          <geometry>
            <mesh>
              <scale>1 1 1</scale>
              <uri>/home/ollie/mmp_ws/src/franka_gazebo/meshes/visual/link5.dae</uri>
            </mesh>
          </geometry>
        </visual>
        <gravity>1</gravity>
        <velocity_decay/>
        <self_collide>0</self_collide>
        <enable_wind>0</enable_wind>
        <kinematic>0</kinematic>
      </link>
      <joint name='panda_joint5' type='revolute'>
        <child>panda_link5</child>
        <parent>panda_link4</parent>
        <axis>
          <xyz>0 0 1</xyz>
          <limit>
            <lower>-2.8973</lower>
            <upper>2.8973</upper>
            <effort>12</effort>
            <velocity>2.61</velocity>
          </limit>
          <dynamics>
            <spring_reference>0</spring_reference>
            <spring_stiffness>0</spring_stiffness>
          </dynamics>
          <use_parent_model_frame>1</use_parent_model_frame>
        </axis>
      </joint>
      <link name='panda_link6'>
        <pose frame=''>-0 0 1.033 1.5708 -1 0</pose>
        <inertial>
          <pose frame=''>0.051051 0.009108 0.010634 0 -0 0</pose>
          <mass>1.55</mass>
          <inertia>
            <ixx>0.00303336</ixx>
            <ixy>-0.000437277</ixy>
            <ixz>0.000629257</ixz>
            <iyy>0.0040448</iyy>
            <iyz>0.000130472</iyz>
            <izz>0.00558234</izz>
          </inertia>
        </inertial>
        <collision name='panda_link6_collision'>
          <pose frame=''>0 0 0 0 -0 0</pose>
          <geometry>
            <mesh>
              <scale>1 1 1</scale>
              <uri>/home/ollie/mmp_ws/src/franka_gazebo/meshes/collision/link6.stl</uri>
            </mesh>
          </geometry>
          <max_contacts>10</max_contacts>
          <surface>
            <contact>
              <ode/>
            </contact>
            <bounce/>
            <friction>
              <torsional>
                <ode/>
              </torsional>
              <ode/>
            </friction>
          </surface>
        </collision>
        <visual name='panda_link6_visual'>
          <pose frame=''>0 0 0 0 -0 0</pose>
          <geometry>
            <mesh>
              <scale>1 1 1</scale>
              <uri>/home/ollie/mmp_ws/src/franka_gazebo/meshes/visual/link6.dae</uri>
            </mesh>
          </geometry>
        </visual>
        <gravity>1</gravity>
        <velocity_decay/>
        <self_collide>0</self_collide>
        <enable_wind>0</enable_wind>
        <kinematic>0</kinematic>
      </link>
      <joint name='panda_joint6' type='revolute'>
        <child>panda_link6</child>
        <parent>panda_link5</parent>
        <axis>
          <xyz>-0 -1 0</xyz>
          <limit>
            <lower>-0.0175</lower>
            <upper>3.7525</upper>
            <effort>12</effort>
            <velocity>2.61</velocity>
          </limit>
          <dynamics>
            <spring_reference>0</spring_reference>
            <spring_stiffness>0</spring_stiffness>
          </dynamics>
          <use_parent_model_frame>1</use_parent_model_frame>
        </axis>
      </joint>
      <link name='panda_link7'>
        <pose frame=''>0.047547 0 1.10705 -2.77381 -0.953267 -0.441481</pose>
        <inertial>
          <pose frame=''>0.005284 0.00521 0.105019 0 -0 0</pose>
          <mass>1.27</mass>
          <inertia>
            <ixx>0.00401245</ixx>
            <ixy>-0.00134501</ixy>
            <ixz>0.000253409</ixz>
            <iyy>0.00401263</iyy>
            <iyz>0.000116421</iyz>
            <izz>0.00334115</izz>
          </inertia>
        </inertial>
        <collision name='panda_link7_collision'>
          <pose frame=''>0 0 0 0 -0 0</pose>
          <geometry>
            <mesh>
              <scale>1 1 1</scale>
              <uri>/home/ollie/mmp_ws/src/franka_gazebo/meshes/collision/link7.stl</uri>
            </mesh>
          </geometry>
          <max_contacts>10</max_contacts>
          <surface>
            <contact>
              <ode/>
            </contact>
            <bounce/>
            <friction>
              <torsional>
                <ode/>
              </torsional>
              <ode/>
            </friction>
          </surface>
        </collision>
        <collision name='panda_link7_fixed_joint_lump__panda_hand_collision_1'>
          <pose frame=''>0 0 0.107 0 0 -0.785398</pose>
          <geometry>
            <mesh>
              <scale>1 1 1</scale>
              <uri>/home/ollie/mmp_ws/src/franka_gazebo/meshes/collision/hand.stl</uri>
            </mesh>
          </geometry>
          <max_contacts>10</max_contacts>
          <surface>
            <contact>
              <ode/>
            </contact>
            <bounce/>
            <friction>
              <torsional>
                <ode/>
              </torsional>
              <ode/>
            </friction>
          </surface>
        </collision>
        <visual name='panda_link7_visual'>
          <pose frame=''>0 0 0 0 -0 0</pose>
          <geometry>
            <mesh>
              <scale>1 1 1</scale>
              <uri>/home/ollie/mmp_ws/src/franka_gazebo/meshes/visual/link7.dae</uri>
            </mesh>
          </geometry>
        </visual>
        <visual name='panda_link7_fixed_joint_lump__panda_hand_visual_1'>
          <pose frame=''>0 0 0.107 0 0 -0.785398</pose>
          <geometry>
            <mesh>
              <scale>1 1 1</scale>
              <uri>/home/ollie/mmp_ws/src/franka_gazebo/meshes/visual/hand.dae</uri>
            </mesh>
          </geometry>
        </visual>
        <velocity_decay/>
        <velocity_decay/>
        <gravity>1</gravity>
        <velocity_decay/>
        <self_collide>0</self_collide>
        <enable_wind>0</enable_wind>
        <kinematic>0</kinematic>
      </link>
      <joint name='panda_joint7' type='revolute'>
        <child>panda_link7</child>
        <parent>panda_link6</parent>
        <axis>
          <xyz>0.841471 -0 -0.540302</xyz>
          <limit>
            <lower>-2.8973</lower>
            <upper>2.8973</upper>
            <effort>12</effort>
            <velocity>2.61</velocity>
          </limit>
          <dynamics>
            <spring_reference>0</spring_reference>
            <spring_stiffness>0</spring_stiffness>
          </dynamics>
          <use_parent_model_frame>1</use_parent_model_frame>
        </axis>
      </joint>
      <link name='panda_leftfinger'>
        <pose frame=''>0.186726 -0 1.01768 2.47018 -0.809178 0.832025</pose>
        <inertial>
          <pose frame=''>0 0.014564 0.022794 0 -0 0</pose>
          <mass>0.1</mass>
          <inertia>
            <ixx>3.01221e-05</ixx>
            <ixy>0</ixy>
            <ixz>0</ixz>
            <iyy>2.95874e-05</iyy>
            <iyz>0</iyz>
            <izz>6.95125e-06</izz>
          </inertia>
        </inertial>
        <collision name='panda_leftfinger_collision'>
          <pose frame=''>0 0 0 0 -0 0</pose>
          <geometry>
            <mesh>
              <scale>1 1 1</scale>
              <uri>/home/ollie/mmp_ws/src/franka_gazebo/meshes/collision/finger.stl</uri>
            </mesh>
          </geometry>
          <max_contacts>10</max_contacts>
          <surface>
            <contact>
              <ode/>
            </contact>
            <bounce/>
            <friction>
              <torsional>
                <ode/>
              </torsional>
              <ode/>
            </friction>
          </surface>
        </collision>
        <visual name='panda_leftfinger_visual'>
          <pose frame=''>0 0 0 0 -0 0</pose>
          <geometry>
            <mesh>
              <scale>1 1 1</scale>
              <uri>/home/ollie/mmp_ws/src/franka_gazebo/meshes/visual/finger.dae</uri>
            </mesh>
          </geometry>
        </visual>
        <gravity>1</gravity>
        <velocity_decay/>
        <self_collide>0</self_collide>
        <enable_wind>0</enable_wind>
        <kinematic>0</kinematic>
      </link>
      <joint name='panda_finger_joint1' type='prismatic'>
        <child>panda_leftfinger</child>
        <parent>panda_link7</parent>
        <axis>
          <xyz>0.275653 -0.860066 0.429305</xyz>
          <limit>
            <lower>-0.001</lower>
            <upper>0.04</upper>
            <effort>20</effort>
            <velocity>0.3</velocity>
          </limit>
          <dynamics>
            <spring_reference>0</spring_reference>
            <spring_stiffness>0</spring_stiffness>
          </dynamics>
          <use_parent_model_frame>1</use_parent_model_frame>
        </axis>
      </joint>
      <link name='panda_rightfinger'>
        <pose frame=''>0.186726 -0 1.01768 2.47018 -0.809178 0.832025</pose>
        <inertial>
          <pose frame=''>0 0.014564 0.022794 0 -0 -3.14159</pose>
          <mass>0.1</mass>
          <inertia>
            <ixx>3.01221e-05</ixx>
            <ixy>0</ixy>
            <ixz>0</ixz>
            <iyy>2.95874e-05</iyy>
            <iyz>0</iyz>
            <izz>6.95125e-06</izz>
          </inertia>
        </inertial>
        <collision name='panda_rightfinger_collision'>
          <pose frame=''>0 0 0 0 -0 -3.14159</pose>
          <geometry>
            <mesh>
              <scale>1 1 1</scale>
              <uri>/home/ollie/mmp_ws/src/franka_gazebo/meshes/collision/finger.stl</uri>
            </mesh>
          </geometry>
          <max_contacts>10</max_contacts>
          <surface>
            <contact>
              <ode/>
            </contact>
            <bounce/>
            <friction>
              <torsional>
                <ode/>
              </torsional>
              <ode/>
            </friction>
          </surface>
        </collision>
        <visual name='panda_rightfinger_visual'>
          <pose frame=''>0 0 0 0 -0 -3.14159</pose>
          <geometry>
            <mesh>
              <scale>1 1 1</scale>
              <uri>/home/ollie/mmp_ws/src/franka_gazebo/meshes/visual/finger.dae</uri>
            </mesh>
          </geometry>
        </visual>
        <gravity>1</gravity>
        <velocity_decay/>
        <self_collide>0</self_collide>
        <enable_wind>0</enable_wind>
        <kinematic>0</kinematic>
      </link>
      <joint name='panda_finger_joint2' type='prismatic'>
        <child>panda_rightfinger</child>
        <parent>panda_link7</parent>
        <axis>
          <xyz>-0.275653 0.860066 -0.429305</xyz>
          <limit>
            <lower>-0.001</lower>
            <upper>0.04</upper>
            <effort>20</effort>
            <velocity>0.3</velocity>
          </limit>
          <dynamics>
            <spring_reference>0</spring_reference>
            <spring_stiffness>0</spring_stiffness>
          </dynamics>
          <use_parent_model_frame>1</use_parent_model_frame>
        </axis>
      </joint>
      <static>0</static>
      <plugin name='gazebo_ros_control' filename='libgazebo_ros_control.so'>
        <robotNamespace/>
      </plugin>
      <pose frame=''>0 0 0 0 -0 0</pose>
    </model>
    <model name='cafe_table'>
      <static>1</static>
      <link name='link'>
        <collision name='surface'>
          <pose frame=''>0 0 0.755 0 -0 0</pose>
          <geometry>
            <box>
              <size>0.913 0.913 0.04</size>
            </box>
          </geometry>
          <max_contacts>10</max_contacts>
          <surface>
            <contact>
              <ode/>
            </contact>
            <bounce/>
            <friction>
              <torsional>
                <ode/>
              </torsional>
              <ode/>
            </friction>
          </surface>
        </collision>
        <collision name='column'>
          <pose frame=''>0 0 0.37 0 -0 0</pose>
          <geometry>
            <box>
              <size>0.042 0.042 0.74</size>
            </box>
          </geometry>
          <max_contacts>10</max_contacts>
          <surface>
            <contact>
              <ode/>
            </contact>
            <bounce/>
            <friction>
              <torsional>
                <ode/>
              </torsional>
              <ode/>
            </friction>
          </surface>
        </collision>
        <collision name='base'>
          <pose frame=''>0 0 0.02 0 -0 0</pose>
          <geometry>
            <box>
              <size>0.56 0.56 0.04</size>
            </box>
          </geometry>
          <max_contacts>10</max_contacts>
          <surface>
            <contact>
              <ode/>
            </contact>
            <bounce/>
            <friction>
              <torsional>
                <ode/>
              </torsional>
              <ode/>
            </friction>
          </surface>
        </collision>
        <visual name='visual'>
          <geometry>
            <mesh>
              <uri>model://cafe_table/meshes/cafe_table.dae</uri>
            </mesh>
          </geometry>
        </visual>
        <self_collide>0</self_collide>
        <enable_wind>0</enable_wind>
        <kinematic>0</kinematic>
      </link>
      <pose frame=''>0.908516 -0.011499 0 0 -0 0</pose>
    </model>
  </world>
</sdf>
