<sdf version='1.6'>
  <world name='default'>
    <light name='sun' type='directional'>
      <cast_shadows>1</cast_shadows>
      <pose frame=''>0 0 10 0 -0 0</pose>
      <diffuse>0.8 0.8 0.8 1</diffuse>
      <specular>0.2 0.2 0.2 1</specular>
      <attenuation>
        <range>1000</range>
        <constant>0.9</constant>
        <linear>0.01</linear>
        <quadratic>0.001</quadratic>
      </attenuation>
      <direction>-0.5 0.1 -0.9</direction>
    </light>
    <model name='ground_plane'>
      <static>1</static>
      <link name='link'>
        <collision name='collision'>
          <geometry>
            <plane>
              <normal>0 0 1</normal>
              <size>100 100</size>
            </plane>
          </geometry>
          <surface>
            <contact>
              <collide_bitmask>65535</collide_bitmask>
              <ode/>
            </contact>
            <friction>
              <ode>
                <mu>100</mu>
                <mu2>50</mu2>
              </ode>
              <torsional>
                <ode/>
              </torsional>
            </friction>
            <bounce/>
          </surface>
          <max_contacts>10</max_contacts>
        </collision>
        <visual name='visual'>
          <cast_shadows>0</cast_shadows>
          <geometry>
            <plane>
              <normal>0 0 1</normal>
              <size>100 100</size>
            </plane>
          </geometry>
          <material>
            <script>
              <uri>file://media/materials/scripts/gazebo.material</uri>
              <name>Gazebo/Grey</name>
            </script>
          </material>
        </visual>
        <self_collide>0</self_collide>
        <enable_wind>0</enable_wind>
        <kinematic>0</kinematic>
      </link>
    </model>
    <gravity>0 0 -9.8</gravity>
    <magnetic_field>6e-06 2.3e-05 -4.2e-05</magnetic_field>
    <atmosphere type='adiabatic'/>
    <physics name='default_physics' default='0' type='ode'>
      <max_step_size>0.001</max_step_size>
      <real_time_factor>1</real_time_factor>
      <real_time_update_rate>1000</real_time_update_rate>
    </physics>
    <scene>
      <ambient>0.4 0.4 0.4 1</ambient>
      <background>0.7 0.7 0.7 1</background>
      <shadows>1</shadows>
    </scene>
    <wind/>
    <spherical_coordinates>
      <surface_model>EARTH_WGS84</surface_model>
      <latitude_deg>0</latitude_deg>
      <longitude_deg>0</longitude_deg>
      <elevation>0</elevation>
      <heading_deg>0</heading_deg>
    </spherical_coordinates>
    <model name='kinect'>
      <pose frame=''>0.375701 0.005515 0.036 0 -0 0</pose>
      <static>1</static>
      <link name='link'>
        <inertial>
          <mass>0.1</mass>
        </inertial>
        <collision name='collision'>
          <geometry>
            <box>
              <size>0.073 0.276 0.072</size>
            </box>
          </geometry>
          <max_contacts>10</max_contacts>
          <surface>
            <contact>
              <ode/>
            </contact>
            <bounce/>
            <friction>
              <torsional>
                <ode/>
              </torsional>
              <ode/>
            </friction>
          </surface>
        </collision>
        <visual name='visual'>
          <geometry>
            <mesh>
              <uri>model://kinect/meshes/kinect.dae</uri>
            </mesh>
          </geometry>
        </visual>
        <sensor name='camera' type='depth'>
          <update_rate>20</update_rate>
          <camera name='__default__'>
            <horizontal_fov>1.0472</horizontal_fov>
            <image>
              <width>640</width>
              <height>480</height>
              <format>R8G8B8</format>
            </image>
            <clip>
              <near>0.05</near>
              <far>3</far>
            </clip>
          </camera>
          <plugin name='camera_plugin' filename='libgazebo_ros_openni_kinect.so'>
            <baseline>0.2</baseline>
            <alwaysOn>1</alwaysOn>
            <updateRate>0.0</updateRate>
            <cameraName>camera_ir</cameraName>
            <imageTopicName>/camera/color/image_raw</imageTopicName>
            <cameraInfoTopicName>/camera/color/camera_info</cameraInfoTopicName>
            <depthImageTopicName>/camera/depth/image_raw</depthImageTopicName>
            <depthImageCameraInfoTopicName>/camera/depth/camera_info</depthImageCameraInfoTopicName>
            <pointCloudTopicName>/camera/depth/points</pointCloudTopicName>
            <frameName>camera_link</frameName>
            <pointCloudCutoff>0.5</pointCloudCutoff>
            <pointCloudCutoffMax>3.0</pointCloudCutoffMax>
            <distortionK1>0</distortionK1>
            <distortionK2>0</distortionK2>
            <distortionK3>0</distortionK3>
            <distortionT1>0</distortionT1>
            <distortionT2>0</distortionT2>
            <CxPrime>0</CxPrime>
            <Cx>0</Cx>
            <Cy>0</Cy>
            <focalLength>0</focalLength>
            <hackBaseline>0</hackBaseline>
          </plugin>
        </sensor>
        <self_collide>0</self_collide>
        <enable_wind>0</enable_wind>
        <kinematic>0</kinematic>
      </link>
    </model>
    <state world_name='default'>
      <sim_time>1107 549000000</sim_time>
      <real_time>86 246928852</real_time>
      <wall_time>1614441497 598873636</wall_time>
      <iterations>85811</iterations>
      <model name='ground_plane'>
        <pose frame=''>0 0 0 0 -0 0</pose>
        <scale>1 1 1</scale>
        <link name='link'>
          <pose frame=''>0 0 0 0 -0 0</pose>
          <velocity>0 0 0 0 -0 0</velocity>
          <acceleration>0 0 0 0 -0 0</acceleration>
          <wrench>0 0 0 0 -0 0</wrench>
        </link>
      </model>
      <model name='kinect'>
        <pose frame=''>0.425305 -0.418825 0.699276 -0 0.593942 0.445789</pose>
        <scale>1 1 1</scale>
        <link name='link'>
          <pose frame=''>0.425305 -0.418825 0.699276 -0 0.593942 0.445789</pose>
          <velocity>0 0 0 0 -0 0</velocity>
          <acceleration>0 0 0 0 -0 0</acceleration>
          <wrench>0 0 0 0 -0 0</wrench>
        </link>
      </model>
      <model name='panda'>
        <pose frame=''>2e-06 -2e-06 2e-05 -0.000128 -7.9e-05 1.1e-05</pose>
        <scale>1 1 1</scale>
        <link name='panda_leftfinger'>
          <pose frame=''>-0.088314 0.000492 1.19893 0.000234 -0.011134 3.13591</pose>
          <velocity>0.002075 -9.2e-05 -0.000373 0.00626 0.028306 0.000392</velocity>
          <acceleration>5.64586 -0.231642 -0.922573 2.58217 -0.686114 -1.63148</acceleration>
          <wrench>0.564586 -0.023164 -0.092257 0 -0 0</wrench>
        </link>
        <link name='panda_link0'>
          <pose frame=''>2e-06 -2e-06 2e-05 -0.000128 -7.9e-05 1.1e-05</pose>
          <velocity>2.2e-05 3e-06 0.002052 0.012338 -0.007025 -0.000192</velocity>
          <acceleration>-0.786462 -1.3306 3.75129 -0.068851 -1.17165 -0.690813</acceleration>
          <wrench>-2.29647 -3.88534 10.9538 0 -0 0</wrench>
        </link>
        <link name='panda_link1'>
          <pose frame=''>-3.1e-05 3.6e-05 0.333021 -9.9e-05 -0.000109 0.002476</pose>
          <velocity>-0.00269 -0.002931 0.002173 0.002169 -0.00894 -0.007422</velocity>
          <acceleration>-4.60483 -5.42699 4.27869 1.3754 0.860734 -0.935786</acceleration>
          <wrench>-12.6172 -14.87 11.7236 0 -0 0</wrench>
        </link>
        <link name='panda_link2'>
          <pose frame=''>-3.1e-05 3.5e-05 0.333021 -1.57089 -3.8e-05 0.002477</pose>
          <velocity>-0.002638 -0.002563 0.002044 -0.000875 0.034463 -0.008016</velocity>
          <acceleration>-0.022613 -4.56697 3.97044 -1.86159 -0.71397 2.53455</acceleration>
          <wrench>-0.061961 -12.5135 10.879 0 -0 0</wrench>
        </link>
        <link name='panda_link3'>
          <pose frame=''>-4.4e-05 5.9e-05 0.649019 -7.7e-05 -2.5e-05 0.002647</pose>
          <velocity>0.008224 -0.001222 0.002282 -0.004236 0.031628 0.007974</velocity>
          <acceleration>13.7707 -0.707436 1.22944 -0.252807 0.401997 -2.66447</acceleration>
          <wrench>32.7743 -1.6837 2.92606 0 -0 0</wrench>
        </link>
        <link name='panda_link4'>
          <pose frame=''>0.082457 0.000278 0.649023 1.57071 -0.005535 0.002638</pose>
          <velocity>0.00796 -0.000578 -0.000586 -0.002139 -0.027759 0.009557</velocity>
          <acceleration>15.0681 -0.258253 -2.94895 2.86888 0.093417 1.08344</acceleration>
          <wrench>35.8622 -0.614642 -7.0185 0 -0 0</wrench>
        </link>
        <link name='panda_link5'>
          <pose frame=''>-0.002167 9.2e-05 1.03256 -0.000124 -0.005528 0.002855</pose>
          <velocity>-0.002537 -0.001186 -0.002816 0.004212 -0.02878 -0.015196</velocity>
          <acceleration>2.15036 0.308469 -5.2682 2.91161 -0.099745 -2.80918</acceleration>
          <wrench>5.89198 0.845205 -14.4349 0 -0 0</wrench>
        </link>
        <link name='panda_link6'>
          <pose frame=''>-0.002166 9.2e-05 1.03256 -1.57067 -0.011123 -3.13873</pose>
          <velocity>-0.002659 -0.001259 -0.002869 0.004063 0.028857 -0.016123</velocity>
          <acceleration>-5.58445 0.556797 -2.84601 -2.64702 -0.105559 -2.38275</acceleration>
          <wrench>-8.6559 0.863036 -4.41132 0 -0 0</wrench>
        </link>
        <link name='panda_link7'>
          <pose frame=''>-0.09016 -0.000159 1.03354 -0.007698 -0.008026 -2.36185</pose>
          <velocity>-0.002689 3e-05 -0.000329 0.006072 0.028825 0.000545</velocity>
          <acceleration>0.979608 -0.000912 -0.818451 -1.40071 -0.137872 -0.274046</acceleration>
          <wrench>1.2441 -0.001158 -1.03943 0 -0 0</wrench>
        </link>
        <link name='panda_rightfinger'>
          <pose frame=''>-0.088307 0.001718 1.19893 0.000234 -0.011133 3.13591</pose>
          <velocity>0.002076 -9.2e-05 -0.000366 0.006261 0.028334 0.000431</velocity>
          <acceleration>5.65355 -0.231691 -0.912571 2.58414 -0.633199 -1.55723</acceleration>
          <wrench>0.565355 -0.023169 -0.091257 0 -0 0</wrench>
        </link>
      </model>
      <light name='sun'>
        <pose frame=''>0 0 10 0 -0 0</pose>
      </light>
    </state>
    <gui fullscreen='0'>
      <camera name='user_camera'>
        <pose frame=''>0.847146 5.53107 2.42011 0 0.231642 -1.52699</pose>
        <view_controller>orbit</view_controller>
        <projection_type>perspective</projection_type>
      </camera>
    </gui>
    <model name='panda'>
      <link name='panda_link0'>
        <pose frame=''>0 0 0 0 -0 0</pose>
        <inertial>
          <pose frame=''>-0.025566 -2.9e-05 0.057332 0 -0 0</pose>
          <mass>2.92</mass>
          <inertia>
            <ixx>0.00782229</ixx>
            <ixy>-1.56192e-05</ixy>
            <ixz>-0.00126006</ixz>
            <iyy>0.0109028</iyy>
            <iyz>1.08234e-05</iyz>
            <izz>0.0102356</izz>
          </inertia>
        </inertial>
        <collision name='panda_link0_collision'>
          <pose frame=''>0 0 0 0 -0 0</pose>
          <geometry>
            <mesh>
              <scale>1 1 1</scale>
              <uri>/home/ollie/mmp_ws/src/franka_gazebo/meshes/collision/link0.stl</uri>
            </mesh>
          </geometry>
          <max_contacts>10</max_contacts>
          <surface>
            <contact>
              <ode/>
            </contact>
            <bounce/>
            <friction>
              <torsional>
                <ode/>
              </torsional>
              <ode/>
            </friction>
          </surface>
        </collision>
        <visual name='panda_link0_visual'>
          <pose frame=''>0 0 0 0 -0 0</pose>
          <geometry>
            <mesh>
              <scale>1 1 1</scale>
              <uri>/home/ollie/mmp_ws/src/franka_gazebo/meshes/visual/link0.dae</uri>
            </mesh>
          </geometry>
        </visual>
        <gravity>1</gravity>
        <velocity_decay/>
        <self_collide>0</self_collide>
        <enable_wind>0</enable_wind>
        <kinematic>0</kinematic>
      </link>
      <joint name='panda_joint_world' type='fixed'>
        <child>panda_link0</child>
        <parent>world</parent>
      </joint>
      <link name='panda_link1'>
        <pose frame=''>0 0 0.333 0 -0 0</pose>
        <inertial>
          <pose frame=''>0 -0.032496 -0.067582 0 -0 0</pose>
          <mass>2.74</mass>
          <inertia>
            <ixx>0.0180417</ixx>
            <ixy>0</ixy>
            <ixz>0</ixz>
            <iyy>0.0159136</iyy>
            <iyz>0.00467584</iyz>
            <izz>0.00620691</izz>
          </inertia>
        </inertial>
        <collision name='panda_link1_collision'>
          <pose frame=''>0 0 0 0 -0 0</pose>
          <geometry>
            <mesh>
              <scale>1 1 1</scale>
              <uri>/home/ollie/mmp_ws/src/franka_gazebo/meshes/collision/link1.stl</uri>
            </mesh>
          </geometry>
          <max_contacts>10</max_contacts>
          <surface>
            <contact>
              <ode/>
            </contact>
            <bounce/>
            <friction>
              <torsional>
                <ode/>
              </torsional>
              <ode/>
            </friction>
          </surface>
        </collision>
        <visual name='panda_link1_visual'>
          <pose frame=''>0 0 0 0 -0 0</pose>
          <geometry>
            <mesh>
              <scale>1 1 1</scale>
              <uri>/home/ollie/mmp_ws/src/franka_gazebo/meshes/visual/link1.dae</uri>
            </mesh>
          </geometry>
        </visual>
        <gravity>1</gravity>
        <velocity_decay/>
        <self_collide>0</self_collide>
        <enable_wind>0</enable_wind>
        <kinematic>0</kinematic>
      </link>
      <joint name='panda_joint1' type='revolute'>
        <child>panda_link1</child>
        <parent>panda_link0</parent>
        <axis>
          <xyz>0 0 1</xyz>
          <limit>
            <lower>-2.8973</lower>
            <upper>2.8973</upper>
            <effort>87</effort>
            <velocity>2.175</velocity>
          </limit>
          <dynamics>
            <spring_reference>0</spring_reference>
            <spring_stiffness>0</spring_stiffness>
          </dynamics>
          <use_parent_model_frame>1</use_parent_model_frame>
        </axis>
      </joint>
      <link name='panda_link2'>
        <pose frame=''>0 0 0.333 -1.5708 0 0</pose>
        <inertial>
          <pose frame=''>0 -0.06861 0.032229 0 -0 0</pose>
          <mass>2.74</mass>
          <inertia>
            <ixx>0.0182856</ixx>
            <ixy>0</ixy>
            <ixz>0</ixz>
            <iyy>0.00621358</iyy>
            <iyz>-0.00472844</iyz>
            <izz>0.0161514</izz>
          </inertia>
        </inertial>
        <collision name='panda_link2_collision'>
          <pose frame=''>0 0 0 0 -0 0</pose>
          <geometry>
            <mesh>
              <scale>1 1 1</scale>
              <uri>/home/ollie/mmp_ws/src/franka_gazebo/meshes/collision/link2.stl</uri>
            </mesh>
          </geometry>
          <max_contacts>10</max_contacts>
          <surface>
            <contact>
              <ode/>
            </contact>
            <bounce/>
            <friction>
              <torsional>
                <ode/>
              </torsional>
              <ode/>
            </friction>
          </surface>
        </collision>
        <visual name='panda_link2_visual'>
          <pose frame=''>0 0 0 0 -0 0</pose>
          <geometry>
            <mesh>
              <scale>1 1 1</scale>
              <uri>/home/ollie/mmp_ws/src/franka_gazebo/meshes/visual/link2.dae</uri>
            </mesh>
          </geometry>
        </visual>
        <gravity>1</gravity>
        <velocity_decay/>
        <self_collide>0</self_collide>
        <enable_wind>0</enable_wind>
        <kinematic>0</kinematic>
      </link>
      <joint name='panda_joint2' type='revolute'>
        <child>panda_link2</child>
        <parent>panda_link1</parent>
        <axis>
          <xyz>0 1 0</xyz>
          <limit>
            <lower>-1.7628</lower>
            <upper>1.7628</upper>
            <effort>87</effort>
            <velocity>2.175</velocity>
          </limit>
          <dynamics>
            <spring_reference>0</spring_reference>
            <spring_stiffness>0</spring_stiffness>
          </dynamics>
          <use_parent_model_frame>1</use_parent_model_frame>
        </axis>
      </joint>
      <link name='panda_link3'>
        <pose frame=''>0 -0 0.649 0 -0 0</pose>
        <inertial>
          <pose frame=''>0.046989 0.031637 -0.031704 0 -0 0</pose>
          <mass>2.38</mass>
          <inertia>
            <ixx>0.00771377</ixx>
            <ixy>-0.00248491</ixy>
            <ixz>-0.00332148</ixz>
            <iyy>0.00989108</iyy>
            <iyz>-0.00217796</iyz>
            <izz>0.00811724</izz>
          </inertia>
        </inertial>
        <collision name='panda_link3_collision'>
          <pose frame=''>0 0 0 0 -0 0</pose>
          <geometry>
            <mesh>
              <scale>1 1 1</scale>
              <uri>/home/ollie/mmp_ws/src/franka_gazebo/meshes/collision/link3.stl</uri>
            </mesh>
          </geometry>
          <max_contacts>10</max_contacts>
          <surface>
            <contact>
              <ode/>
            </contact>
            <bounce/>
            <friction>
              <torsional>
                <ode/>
              </torsional>
              <ode/>
            </friction>
          </surface>
        </collision>
        <visual name='panda_link3_visual'>
          <pose frame=''>0 0 0 0 -0 0</pose>
          <geometry>
            <mesh>
              <scale>1 1 1</scale>
              <uri>/home/ollie/mmp_ws/src/franka_gazebo/meshes/visual/link3.dae</uri>
            </mesh>
          </geometry>
        </visual>
        <gravity>1</gravity>
        <velocity_decay/>
        <self_collide>0</self_collide>
        <enable_wind>0</enable_wind>
        <kinematic>0</kinematic>
      </link>
      <joint name='panda_joint3' type='revolute'>
        <child>panda_link3</child>
        <parent>panda_link2</parent>
        <axis>
          <xyz>0 0 1</xyz>
          <limit>
            <lower>-2.8973</lower>
            <upper>2.8973</upper>
            <effort>87</effort>
            <velocity>2.175</velocity>
          </limit>
          <dynamics>
            <spring_reference>0</spring_reference>
            <spring_stiffness>0</spring_stiffness>
          </dynamics>
          <use_parent_model_frame>1</use_parent_model_frame>
        </axis>
      </joint>
      <link name='panda_link4'>
        <pose frame=''>0.0825 -0 0.649 1.5708 -0 0</pose>
        <inertial>
          <pose frame=''>-0.036045 0.033685 0.031882 0 -0 0</pose>
          <mass>2.38</mass>
          <inertia>
            <ixx>0.00799664</ixx>
            <ixy>0.00347096</ixy>
            <ixz>-0.00241223</ixz>
            <iyy>0.00825391</iyy>
            <iyz>0.00235774</iyz>
            <izz>0.0102515</izz>
          </inertia>
        </inertial>
        <collision name='panda_link4_collision'>
          <pose frame=''>0 0 0 0 -0 0</pose>
          <geometry>
            <mesh>
              <scale>1 1 1</scale>
              <uri>/home/ollie/mmp_ws/src/franka_gazebo/meshes/collision/link4.stl</uri>
            </mesh>
          </geometry>
          <max_contacts>10</max_contacts>
          <surface>
            <contact>
              <ode/>
            </contact>
            <bounce/>
            <friction>
              <torsional>
                <ode/>
              </torsional>
              <ode/>
            </friction>
          </surface>
        </collision>
        <visual name='panda_link4_visual'>
          <pose frame=''>0 0 0 0 -0 0</pose>
          <geometry>
            <mesh>
              <scale>1 1 1</scale>
              <uri>/home/ollie/mmp_ws/src/franka_gazebo/meshes/visual/link4.dae</uri>
            </mesh>
          </geometry>
        </visual>
        <gravity>1</gravity>
        <velocity_decay/>
        <self_collide>0</self_collide>
        <enable_wind>0</enable_wind>
        <kinematic>0</kinematic>
      </link>
      <joint name='panda_joint4' type='revolute'>
        <child>panda_link4</child>
        <parent>panda_link3</parent>
        <axis>
          <xyz>0 -1 0</xyz>
          <limit>
            <lower>-3.0718</lower>
            <upper>0.0698</upper>
            <effort>87</effort>
            <velocity>2.175</velocity>
          </limit>
          <dynamics>
            <spring_reference>0</spring_reference>
            <spring_stiffness>0</spring_stiffness>
          </dynamics>
          <use_parent_model_frame>1</use_parent_model_frame>
        </axis>
      </joint>
      <link name='panda_link5'>
        <pose frame=''>-0 0 1.033 0 -0 0</pose>
        <inertial>
          <pose frame=''>0 0.061043 -0.104176 0 -0 0</pose>
          <mass>2.74</mass>
          <inertia>
            <ixx>0.0303714</ixx>
            <ixy>6.50284e-07</ixy>
            <ixz>-1.05129e-05</ixz>
            <iyy>0.0288753</iyy>
            <iyz>-0.00775653</iyz>
            <izz>0.00444134</izz>
          </inertia>
        </inertial>
        <collision name='panda_link5_collision'>
          <pose frame=''>0 0 0 0 -0 0</pose>
          <geometry>
            <mesh>
              <scale>1 1 1</scale>
              <uri>/home/ollie/mmp_ws/src/franka_gazebo/meshes/collision/link5.stl</uri>
            </mesh>
          </geometry>
          <max_contacts>10</max_contacts>
          <surface>
            <contact>
              <ode/>
            </contact>
            <bounce/>
            <friction>
              <torsional>
                <ode/>
              </torsional>
              <ode/>
            </friction>
          </surface>
        </collision>
        <visual name='panda_link5_visual'>
          <pose frame=''>0 0 0 0 -0 0</pose>
          <geometry>
            <mesh>
              <scale>1 1 1</scale>
              <uri>/home/ollie/mmp_ws/src/franka_gazebo/meshes/visual/link5.dae</uri>
            </mesh>
          </geometry>
        </visual>
        <gravity>1</gravity>
        <velocity_decay/>
        <self_collide>0</self_collide>
        <enable_wind>0</enable_wind>
        <kinematic>0</kinematic>
      </link>
      <joint name='panda_joint5' type='revolute'>
        <child>panda_link5</child>
        <parent>panda_link4</parent>
        <axis>
          <xyz>0 0 1</xyz>
          <limit>
            <lower>-2.8973</lower>
            <upper>2.8973</upper>
            <effort>12</effort>
            <velocity>2.61</velocity>
          </limit>
          <dynamics>
            <spring_reference>0</spring_reference>
            <spring_stiffness>0</spring_stiffness>
          </dynamics>
          <use_parent_model_frame>1</use_parent_model_frame>
        </axis>
      </joint>
      <link name='panda_link6'>
        <pose frame=''>-0 0 1.033 1.5708 -1 0</pose>
        <inertial>
          <pose frame=''>0.051051 0.009108 0.010634 0 -0 0</pose>
          <mass>1.55</mass>
          <inertia>
            <ixx>0.00303336</ixx>
            <ixy>-0.000437277</ixy>
            <ixz>0.000629257</ixz>
            <iyy>0.0040448</iyy>
            <iyz>0.000130472</iyz>
            <izz>0.00558234</izz>
          </inertia>
        </inertial>
        <collision name='panda_link6_collision'>
          <pose frame=''>0 0 0 0 -0 0</pose>
          <geometry>
            <mesh>
              <scale>1 1 1</scale>
              <uri>/home/ollie/mmp_ws/src/franka_gazebo/meshes/collision/link6.stl</uri>
            </mesh>
          </geometry>
          <max_contacts>10</max_contacts>
          <surface>
            <contact>
              <ode/>
            </contact>
            <bounce/>
            <friction>
              <torsional>
                <ode/>
              </torsional>
              <ode/>
            </friction>
          </surface>
        </collision>
        <visual name='panda_link6_visual'>
          <pose frame=''>0 0 0 0 -0 0</pose>
          <geometry>
            <mesh>
              <scale>1 1 1</scale>
              <uri>/home/ollie/mmp_ws/src/franka_gazebo/meshes/visual/link6.dae</uri>
            </mesh>
          </geometry>
        </visual>
        <gravity>1</gravity>
        <velocity_decay/>
        <self_collide>0</self_collide>
        <enable_wind>0</enable_wind>
        <kinematic>0</kinematic>
      </link>
      <joint name='panda_joint6' type='revolute'>
        <child>panda_link6</child>
        <parent>panda_link5</parent>
        <axis>
          <xyz>-0 -1 0</xyz>
          <limit>
            <lower>-0.0175</lower>
            <upper>3.7525</upper>
            <effort>12</effort>
            <velocity>2.61</velocity>
          </limit>
          <dynamics>
            <spring_reference>0</spring_reference>
            <spring_stiffness>0</spring_stiffness>
          </dynamics>
          <use_parent_model_frame>1</use_parent_model_frame>
        </axis>
      </joint>
      <link name='panda_link7'>
        <pose frame=''>0.047547 0 1.10705 -2.77381 -0.953267 -0.441481</pose>
        <inertial>
          <pose frame=''>0.005284 0.00521 0.105019 0 -0 0</pose>
          <mass>1.27</mass>
          <inertia>
            <ixx>0.00401245</ixx>
            <ixy>-0.00134501</ixy>
            <ixz>0.000253409</ixz>
            <iyy>0.00401263</iyy>
            <iyz>0.000116421</iyz>
            <izz>0.00334115</izz>
          </inertia>
        </inertial>
        <collision name='panda_link7_collision'>
          <pose frame=''>0 0 0 0 -0 0</pose>
          <geometry>
            <mesh>
              <scale>1 1 1</scale>
              <uri>/home/ollie/mmp_ws/src/franka_gazebo/meshes/collision/link7.stl</uri>
            </mesh>
          </geometry>
          <max_contacts>10</max_contacts>
          <surface>
            <contact>
              <ode/>
            </contact>
            <bounce/>
            <friction>
              <torsional>
                <ode/>
              </torsional>
              <ode/>
            </friction>
          </surface>
        </collision>
        <collision name='panda_link7_fixed_joint_lump__panda_hand_collision_1'>
          <pose frame=''>0 0 0.107 0 0 -0.785398</pose>
          <geometry>
            <mesh>
              <scale>1 1 1</scale>
              <uri>/home/ollie/mmp_ws/src/franka_gazebo/meshes/collision/hand.stl</uri>
            </mesh>
          </geometry>
          <max_contacts>10</max_contacts>
          <surface>
            <contact>
              <ode/>
            </contact>
            <bounce/>
            <friction>
              <torsional>
                <ode/>
              </torsional>
              <ode/>
            </friction>
          </surface>
        </collision>
        <visual name='panda_link7_visual'>
          <pose frame=''>0 0 0 0 -0 0</pose>
          <geometry>
            <mesh>
              <scale>1 1 1</scale>
              <uri>/home/ollie/mmp_ws/src/franka_gazebo/meshes/visual/link7.dae</uri>
            </mesh>
          </geometry>
        </visual>
        <visual name='panda_link7_fixed_joint_lump__panda_hand_visual_1'>
          <pose frame=''>0 0 0.107 0 0 -0.785398</pose>
          <geometry>
            <mesh>
              <scale>1 1 1</scale>
              <uri>/home/ollie/mmp_ws/src/franka_gazebo/meshes/visual/hand.dae</uri>
            </mesh>
          </geometry>
        </visual>
        <velocity_decay/>
        <velocity_decay/>
        <gravity>1</gravity>
        <velocity_decay/>
        <self_collide>0</self_collide>
        <enable_wind>0</enable_wind>
        <kinematic>0</kinematic>
      </link>
      <joint name='panda_joint7' type='revolute'>
        <child>panda_link7</child>
        <parent>panda_link6</parent>
        <axis>
          <xyz>0.841471 -0 -0.540302</xyz>
          <limit>
            <lower>-2.8973</lower>
            <upper>2.8973</upper>
            <effort>12</effort>
            <velocity>2.61</velocity>
          </limit>
          <dynamics>
            <spring_reference>0</spring_reference>
            <spring_stiffness>0</spring_stiffness>
          </dynamics>
          <use_parent_model_frame>1</use_parent_model_frame>
        </axis>
      </joint>
      <link name='panda_leftfinger'>
        <pose frame=''>0.186726 -0 1.01768 2.47018 -0.809178 0.832025</pose>
        <inertial>
          <pose frame=''>0 0.014564 0.022794 0 -0 0</pose>
          <mass>0.1</mass>
          <inertia>
            <ixx>3.01221e-05</ixx>
            <ixy>0</ixy>
            <ixz>0</ixz>
            <iyy>2.95874e-05</iyy>
            <iyz>0</iyz>
            <izz>6.95125e-06</izz>
          </inertia>
        </inertial>
        <collision name='panda_leftfinger_collision'>
          <pose frame=''>0 0 0 0 -0 0</pose>
          <geometry>
            <mesh>
              <scale>1 1 1</scale>
              <uri>/home/ollie/mmp_ws/src/franka_gazebo/meshes/collision/finger.stl</uri>
            </mesh>
          </geometry>
          <max_contacts>10</max_contacts>
          <surface>
            <contact>
              <ode/>
            </contact>
            <bounce/>
            <friction>
              <torsional>
                <ode/>
              </torsional>
              <ode/>
            </friction>
          </surface>
        </collision>
        <visual name='panda_leftfinger_visual'>
          <pose frame=''>0 0 0 0 -0 0</pose>
          <geometry>
            <mesh>
              <scale>1 1 1</scale>
              <uri>/home/ollie/mmp_ws/src/franka_gazebo/meshes/visual/finger.dae</uri>
            </mesh>
          </geometry>
        </visual>
        <gravity>1</gravity>
        <velocity_decay/>
        <self_collide>0</self_collide>
        <enable_wind>0</enable_wind>
        <kinematic>0</kinematic>
      </link>
      <joint name='panda_finger_joint1' type='prismatic'>
        <child>panda_leftfinger</child>
        <parent>panda_link7</parent>
        <axis>
          <xyz>0.275653 -0.860066 0.429305</xyz>
          <limit>
            <lower>-0.001</lower>
            <upper>0.04</upper>
            <effort>20</effort>
            <velocity>0.3</velocity>
          </limit>
          <dynamics>
            <spring_reference>0</spring_reference>
            <spring_stiffness>0</spring_stiffness>
          </dynamics>
          <use_parent_model_frame>1</use_parent_model_frame>
        </axis>
      </joint>
      <link name='panda_rightfinger'>
        <pose frame=''>0.186726 -0 1.01768 2.47018 -0.809178 0.832025</pose>
        <inertial>
          <pose frame=''>0 0.014564 0.022794 0 -0 -3.14159</pose>
          <mass>0.1</mass>
          <inertia>
            <ixx>3.01221e-05</ixx>
            <ixy>0</ixy>
            <ixz>0</ixz>
            <iyy>2.95874e-05</iyy>
            <iyz>0</iyz>
            <izz>6.95125e-06</izz>
          </inertia>
        </inertial>
        <collision name='panda_rightfinger_collision'>
          <pose frame=''>0 0 0 0 -0 -3.14159</pose>
          <geometry>
            <mesh>
              <scale>1 1 1</scale>
              <uri>/home/ollie/mmp_ws/src/franka_gazebo/meshes/collision/finger.stl</uri>
            </mesh>
          </geometry>
          <max_contacts>10</max_contacts>
          <surface>
            <contact>
              <ode/>
            </contact>
            <bounce/>
            <friction>
              <torsional>
                <ode/>
              </torsional>
              <ode/>
            </friction>
          </surface>
        </collision>
        <visual name='panda_rightfinger_visual'>
          <pose frame=''>0 0 0 0 -0 -3.14159</pose>
          <geometry>
            <mesh>
              <scale>1 1 1</scale>
              <uri>/home/ollie/mmp_ws/src/franka_gazebo/meshes/visual/finger.dae</uri>
            </mesh>
          </geometry>
        </visual>
        <gravity>1</gravity>
        <velocity_decay/>
        <self_collide>0</self_collide>
        <enable_wind>0</enable_wind>
        <kinematic>0</kinematic>
      </link>
      <joint name='panda_finger_joint2' type='prismatic'>
        <child>panda_rightfinger</child>
        <parent>panda_link7</parent>
        <axis>
          <xyz>-0.275653 0.860066 -0.429305</xyz>
          <limit>
            <lower>-0.001</lower>
            <upper>0.04</upper>
            <effort>20</effort>
            <velocity>0.3</velocity>
          </limit>
          <dynamics>
            <spring_reference>0</spring_reference>
            <spring_stiffness>0</spring_stiffness>
          </dynamics>
          <use_parent_model_frame>1</use_parent_model_frame>
        </axis>
      </joint>
      <static>0</static>
      <plugin name='gazebo_ros_control' filename='libgazebo_ros_control.so'>
        <robotNamespace/>
      </plugin>
      <pose frame=''>0 0 0 0 -0 0</pose>
    </model>
  </world>
</sdf>
